Workbook

Sheet BALANCE SHEET
A1: Consolidated statement of financial position | B1: As at March 31, 2025 | C1: As at March 31, 2024
A2: ASSETS
A3: Current assets
A4: Cash and cash equivalents | B4: 8342 | C4: 9016
A5: Bank deposits | B5: 6215 | C5: 3799
A6: Investments | B6: 30689 | C6: 31481
A7: Trade receivables
A8: Billed | B8: 50142 | C8: 44434
A9: Unbilled | B9: 8904 | C9: 9143
A10: Other financial assets | B10: 3657 | C10: 2665
A11: Income tax assets (net) | B11: 257 | C11: 151
A12: Other assets | B12: 14805 | C12: 12295
A13: Total current assets | B13: 1,23,011 | C13: 1,12,984
A14: Non-current assets
A15: Bank deposits | B15: 1709 | C15: 2248
A16: Investments | B16: 275 | C16: 281
A17: Trade receivables
A18: Billed | B18: 91 | C18: 127
A19: Unbilled | B19: 38 | C19: 16
A20: Other financial assets | B20: 1047 | C20: 1026
A21: Income tax assets (net) | B21: 1569 | C21: 1600
A22: Deferred tax assets (net) | B22: 3540 | C22: 3369
A23: Property, plant and equipment | B23: 12932 | C23: 11224
A24: Right-of-use assets | B24: 9275 | C24: 7886
A25: Goodwill | B25: 4024 | C25: 3989
A26: Other intangible assets | B26: 940 | C26: 510
A27: Other assets | B27: 3304 | C27: 3312
A28: Total non-current assets | B28: 38744 | C28: 35588
A29: TOTAL ASSETS | B29: 1,61,755 | C29: 1,48,572
A30: LIABILITIES AND EQUITY
A31: Liabilities
A32: Current liabilities
A33: Lease liabilities | B33: 1554 | C33: 1505
A34: Trade payables | B34: 13909 | C34: 9981
A35: Other financial liabilities | B35: 8542 | C35: 8362
A36: Unearned and deferred revenue | B36: 4028 | C36: 3640
A37: Other liabilities | B37: 7188 | C37: 6524
A38: Provisions | B38: 180 | C38: 140
A39: Employee benefit obligations | B39: 4885 | C39: 4519
A40: Income tax liabilities (net) | B40: 12715 | C40: 11433
...

Sheet P & L
A1: Consolidated statement of profit or loss and other comprehensive income | B1: Year ended March 31, 2025 | C1: Year ended March 31, 2024
A2: Revenue | B2: 255324 | C2: 240893
A3: Cost of revenue | B3: 1,55,994 | C3: 1,43,595
A4: Gross profit | B4: =B2-B3 -> 99330 | C4: =C2-C3 -> 97298
A5: Operating expenses
A6: Selling, general and administrative expenses
A7: Settlement of legal claim | B7: - | C7: 958
A8: Others | B8: 37165 | C8: 37987
A9: Total Selling, general and administrative expenses | B9: 37165 | C9: 38945
A10: Operating profit | B10: 62165 | C10: 58353
A11: Other income
A12: Finance and other income | B12: 3343 | C12: 3822
A13: Finance costs | B13: -796 | C13: -778
A14: Other gains (net) | B14: 619 | C14: 600
A15: Other income (net) | B15: =SUM(B12:B14) -> 3166 | C15: =SUM(C12:C14) -> 3644
A16: Profit before taxes | B16: =B10+B15 -> 65331 | C16: =C10+C15 -> 61997
A17: Income tax expense | B17: 16534 | C17: 15898
A18: Profit for the year | B18: =B16-B17 -> 48797 | C18: =C16-C17 -> 46099
A19: Other comprehensive income (OCI)
A20: Items that will not be reclassified subsequently to profit or loss
A21: Remeasurement of defined employee benefit plans | B21: -88 | C21: -13
A22: Net change in fair value of investments in equity shares | B22: -24 | C22: -6
A23: Items that will be reclassified subsequently to profit or loss
A24: Net change in fair value of investments other than equity shares carried at | B24: 444 | C24: 200
A25: fair value through OCI
A26: Net change in intrinsic value of derivatives designated as | B26: - | C26: 1
A27: cash flow hedges
A28: Net change in time value of derivatives designated as | B28: -6 | C28: 10
A29: cash flow hedges
A30: Exchange differences on translation of foreign operations | B30: 266 | C30: 50
A31: Total other comprehensive income / (losses), net of tax | B31: 592 | C31: 242
A32: Total comprehensive income for the year | B32: 49389 | C32: 46341
A33: Profit for the year attributable to:
A34: Shareholders of the Company | B34: 48553 | C34: 45908
A35: Non-controlling interests | B35: 244 | C35: 191
B36: 48797 | C36: 46099
A37: Other comprehensive income for the year attributable to:
A38: Shareholders of the Company | B38: 574 | C38: 304
A39: Non-controlling interests | B39: 18 | C39: -62
B40: 592 | C40: 242
...

Sheet CHNAGE IN EQUITY
A1: TATA CONSULTANCY SERVICES LIMITED Consolidated statement of changes in equity
B2: Total equity | C2: Share capital | D2: Retained earnings | E2: Special Economic Zone re-investment reserve | F2: Foreign currency translation reserve | G2: Cash flow hedging reserve | I2: Investment revaluation reserve | J2: Equity attributable to shareholders of the Company | K2: Noncontrolling interests | L2: Total equity
G3: Intrinsic value | H3: Time value
A4: Balance as at April 1, 2024 | B4: 361,80,87,518 | C4: 362 | D4: 72926 | E4: 16234 | F4: 2864 | G4: 9 | H4: -18 | I4: 235 | J4: 92612 | K4: 830 | L4: 93442
A5: Profit for the year | B5: - | C5: - | D5: 48553 | E5: - | F5: - | G5: - | H5: - | I5: - | J5: 48553 | K5: 244 | L5: 48797
A6: Other comprehensive income / (losses) | B6: - | C6: - | D6: -88 | E6: - | F6: 248 | G6: - | H6: -6 | I6: 420 | J6: 574 | K6: 18 | L6: 592
A7: Total comprehensive income | B7: - | C7: - | D7: 48465 | E7: - | F7: 248 | G7: - | H7: -6 | I7: 420 | J7: 49127 | K7: 262 | L7: 49389
A8: Dividend | B8: - | C8: - | D8: -44864 | E8: - | F8: - | G8: - | H8: - | I8: - | J8: -44864 | K8: -98 | L8: -44962
A9: Transfer from Special Economic Zone | B9: - | C9: - | D9: 15149 | E9: -15149 | F9: - | G9: - | H9: - | I9: - | J9: - | K9: - | L9: -
A10: re-investment reserve
A11: Sale of shares to non-controlling interests | B11: - | C11: - | D11: 7 | E11: - | F11: - | G11: - | H11: - | I11: - | J11: 7 | K11: 21 | L11: 28
A12: Balance as at March 31, 2025 | B12: 361,80,87,518 | C12: 362 | D12: 91683 | E12: 1085 | F12: 3112 | G12: 9 | H12: -24 | I12: 655 | J12: 96882 | K12: 1015 | L12: 97897
A13: Balance as at April 1, 2023 | B13: 365,90,51,373 | C13: 366 | D13: 77594 | E13: 11809 | F13: 2752 | G13: 8 | H13: -28 | I13: 41 | J13: 92542 | K13: 782 | L13: 93324
A14: Profit for the year | B14: - | C14: - | D14: 45908 | E14: - | F14: - | G14: - | H14: - | I14: - | J14: 45908 | K14: 191 | L14: 46099
A15: Other comprehensive income / (losses) | B15: - | C15: - | D15: -13 | E15: - | F15: 112 | G15: 1 | H15: 10 | I15: 194 | J15: 304 | K15: -62 | L15: 242
A16: Total comprehensive income | B16: - | C16: - | D16: 45895 | E16: - | F16: 112 | G16: 1 | H16: 10 | I16: 194 | J16: 46212 | K16: 129 | L16: 46341
A17: Dividend | B17: - | C17: - | D17: -25137 | E17: - | F17: - | G17: - | H17: - | I17: - | J17: -25137 | K17: -81 | L17: -25218
A18: Buy-back of equity shares | B18: (409,63,855) | C18: -4 | D18: -16996 | E18: - | F18: - | G18: - | H18: - | I18: - | J18: -17000 | K18: - | L18: -17000
A19: Tax on buy-back of equity shares | B19: - | C19: - | D19: -3959 | E19: - | F19: - | G19: - | H19: - | I19: - | J19: -3959 | K19: - | L19: -3959
A20: Expenses for buy-back of equity shares | B20: - | C20: - | D20: -46 | E20: - | F20: - | G20: - | H20: - | I20: - | J20: -46 | K20: - | L20: -46
A21: Transfer to Special Economic Zone | B21: - | C21: - | D21: -9875 | E21: 9875 | F21: - | G21: - | H21: - | I21: - | J21: - | K21: - | L21: -
A22: re-investment reserve
A23: Transfer from Special Economic Zone | B23: - | C23: - | D23: 5450 | E23: -5450 | F23: - | G23: - | H23: - | I23: - | J23: - | K23: - | L23: -
A24: re-investment reserve
A25: Balance as at March 31, 2024 | B25: 361,80,87,518 | C25: 362 | D25: 72926 | E25: 16234 | F25: 2864 | G25: 9 | H25: -18 | I25: 235 | J25: 92612 | K25: 830 | L25: 93442

Sheet CASH FLOW STATEMENT
B1: Year ended March 31, 2025 | C1: Year ended March 31, 2024
A2: Cash flows from operating activities
A3: Profit for the year | B3: 48797 | C3: 46099
A4: Adjustments for: Depreciation and amortisation expense | B4: 5242 | C4: 4985
A5: Bad debts and advances written off, allowance for expected credit losses and | B5: 128 | C5: 114
A6: doubtful advances (net) Income tax expense | B6: 16534 | C6: 15898
A7: Net gain on lease modification | B7: -15 | C7: -7
A8: Unrealised foreign exchange gain | B8: -1 | C8: -17
A9: Net gain on disposal of property, plant and equipment | B9: -20 | C9: -7
A10: Net gain on disposal / fair valuation of investments | B10: -4 | C10: -36
A11: Dividend reinvested | B11: -3 | C11: -14
A12: Operating profit before working capital changes Net change in Trade receivables | B12: 70658 | C12: 67015
A13: Billed | B13: -5519 | C13: -3327
A14: Unbilled | B14: 291 | C14: -5
... A23: Net cash flows generated from operating activities | B23: 51426 | C23: 46932
A25: Cash flows from investing activities
A26: Bank deposits placed | B26: -10496 | C26: -9471
A27: Purchase of investments* | B27: (1,45,962) | C27: (1,41,011)
A28: Payment for purchase of property, plant and equipment | B28: -2917 | C28: -2202
A29: Payment including advances for acquiring right-of-use assets | B29: -76 | C29: -30
A30: Payment for purchase of intangible assets | B30: -944 | C30: -442
A31: Loan given | B31: -29 | C31: -
A32: Acquisition of assets (Refer note 20) | B32: -1063 | C32: -
A33: Proceeds from bank deposits | B33: 8177 | C33: 8089
A34: Proceeds from inter-corporate deposits | B34: 170 | C34: 846
A35: Proceeds from disposal / redemption of investments* | B35: 1,47,433 | C35: 1,46,928
A36: Proceeds from sub-lease receivable | B36: 5 | C36: 3
A37: Proceeds from disposal of property, plant and equipment | B37: 23 | C37: 17
A38: Proceeds from disposal of intangible assets | B38: - | C38: 7
A39: Loan recovered | B39: 3 | C39: -
A40: Net cash flows generated from / (used in) investing activities | B40: -5676 | C40: 2734
A42: Cash flows from financing activities
A43: Repayment of lease liabilities | B43: -1664 | C43: -1614
A44: Dividend paid | B44: -44864 | C44: -25137
A45: Dividend paid to non-controlling interests | B45: -98 | C45: -81
A46: Transfer of funds to buy-back escrow account | B46: - | C46: -425
A47: Transfer of funds from buy-back escrow account | B47: - | C47: 425
A48: Expenses for buy-back of equity shares | B48: - | C48: -46
A49: Tax on buy-back of equity shares | B49: - | C49: -3959
A50: Buy-back of equity shares | B50: - | C50: -17000
...

Sheet SUMMARY
B1: BALANCE SHEET | F1: PROFIT AND LOSS | J1: CASH FLOW STATEMENT | N1: EQUITY
B3: Particulars | C3: 2025 | D3: 2024 | F3: Particulars | G3: 2025 | H3: 2024 | J3: Particulars | K3: 2025 | L3: 2024 | N3: Particulars | O3: 2025 | P3: 2024
B4: Cash and cash equivalents | C4: 8342 | D4: 9016 | F4: Revenue | G4: 255324 | H4: 240893 | J4: Operating Cash Flow | K4: 51426 | L4: 46932 | N4: Opening Equity | O4: 93442 | P4: 93324
B5: Bank deposits (Current) | C5: 6215 | D5: 3799 | F5: Cost of revenue | G5: 155994 | H5: 143595 | J5: Investing Cash Flow | K5: -5676 | L5: 2734 | N5: Profit for the year | O5: 48797 | P5: 46099
B6: Investments (Current) | C6: 30689 | D6: 31481 | F6: Gross profit | G6: 99330 | H6: 97298 | J6: Financing Cash Flow | K6: -46598 | L6: -47837 | N6: Dividend | O6: -44864 | P6: -25137
B7: Trade receivables - Billed | C7: 50142 | D7: 44434 | F7: Operating profit | G7: 62165 | H7: 58353 | J7: Net Change in Cash | K7: -848 | L7: 1829 | N7: Closing Equity | O7: 97897 | P7: 93442
B8: Trade receivables - Unbilled | C8: 8904 | D8: 9143 | F8: Profit before tax | G8: 65331 | H8: 61997 | J8: Closing Cash | K8: 8342 | L8: 9016
B9: Other financial assets (Current) | C9: 3657 | D9: 2665 | F9: Profit for the year | G9: 48797 | H9: 46099
B10: Income tax assets (Current) | C10: 257 | D10: 151 | F10: EPS | G10: 134.19 | H10: 125.88
B11: Other assets (Current) | C11: 14805 | D11: 12295
B12: Total Current Assets | C12: 123011 | D12: 112984
B13: Total Non-current Assets | C13: 38744 | D13: 35588
B14: TOTAL ASSETS | C14: 161755 | D14: 148572
B15: Total Current Liabilities | C15: 53001 | D15: 46104
B16: Total Non-current Liabilities | C16: 10857 | D16: 9026
B17: TOTAL LIABILITIES | C17: 63858 | D17: 55130
B18: TOTAL EQUITY | C18: 97897 | D18: 93442

Sheet RATIO ANALYSIS 
B2: Ratio | C2: Formula | D2: 2025 | E2: 2024 | G2: change_pct
B3: Current Ratio | C3: Current Assets / Current Liabilities | D3: =SUMMARY!C12/SUMMARY!C15 -> 2.3209185 | E3: =SUMMARY!D12/SUMMARY!D15 -> 2.4506334 | G3: =((D3-E3)/E3)*100 -> -5.2931165
B4: Quick Ratio | C4: (CA - Inventory)/CL | D4: =SUMMARY!C12/SUMMARY!C15 -> 2.3209185 | E4: =SUMMARY!D12/SUMMARY!D15 -> 2.4506334 | G4: =((D4-E4)/E4)*100 -> -5.2931165 | I4: <-- TCS HAS NO INVENTORY
B5: Net Profit Margin | C5: Net Profit / Revenue | D5: =SUMMARY!G9/SUMMARY!G4 -> 0.19111795 | E5: =SUMMARY!H9/SUMMARY!H4 -> 0.19136712 | G5: =((D5-E5)/E5)*100 -> -0.13020492
B6: Operating Margin | C6: Operating Profit / Revenue | D6: =SUMMARY!G7/SUMMARY!G4 -> 0.24347496 | E6: =SUMMARY!H7/SUMMARY!H4 -> 0.24223618 | G6: =((D6-E6)/E6)*100 -> 0.51139254
B7: ROE | C7: Net Profit / Equity | D7: =SUMMARY!G9/SUMMARY!O7 -> 0.49845246 | E7: =SUMMARY!H9/SUMMARY!P7 -> 0.49334346 | G7: =((D7-E7)/E7)*100 -> 1.035585
B8: ROA | C8: Net Profit / Total Assets | D8: =SUMMARY!G9/SUMMARY!C14 -> 0.30167228 | E8: =SUMMARY!H9/SUMMARY!D14 -> 0.31028054 | G8: =((D8-E8)/E8)*100 -> -2.7743459
B9: Debt to Equity | C9: Debt / Equity | D9: =SUMMARY!C17/SUMMARY!O7 -> 0.65229782 | E9: =SUMMARY!D17/SUMMARY!P7 -> 0.58999165 | G9: =((D9-E9)/E9)*100 -> 10.560517
B10: Asset Turnover | C10: Revenue / Total Assets | D10: =SUMMARY!G4/SUMMARY!C14 -> 1.5784613 | E10: =SUMMARY!H4/SUMMARY!D14 -> 1.621389 | G10: =((D10-E10)/E10)*100 -> -2.6475882
