Workbook

Sheet Cover
A1: INDIAN EQUITY ANALYSIS ADITYA BIRLA FASHION & RETAIL | DAM CAPITAL ADVISORS FY2020 – FY2024
A5: NSE: ABFRL | NSE: DAMCAP | All figures in INR Crores | FY ends March 31
B7: ① Financial Data | E7: 3-statement data: P&L, Balance Sheet, Cash Flow (FY2020–FY2024)
B8: ② Ratio Analysis | E8: 25+ ratios — Liquidity, Profitability, Efficiency, Leverage, CF
B9: ③ Visualizations | E9: Charts for ABFRL and DAM Capital side by side
B10: ④ Interpretation | E10: Strengths, risks & strategic commentary per company
B11: ⑦ IRR & NPV Analysis | E11: IRR, NPV, WACC, DCF model with 5-year FCF projections for both companies
B12: ⑧ Risk & Reward Scorecard | E12: Weighted risk/reward scoring, investment verdict, risk-reward ratio comparison
B15: FY2024 SNAPSHOT
B16: ABFRL Revenue | C16: ABFRL EBITDA Margin | D16: ABFRL Net Income | E16: ABFRL D/E | F16: DAM Revenue | G16: DAM Net Margin | H16: DAM ROE | I16: DAM Net Debt
B17: ₹14,688 Cr | C17: 14.6% | D17: −₹147 Cr | E17: 1.12x | F17: ₹289.6 Cr | G17: 44.6% | H17: 54.5% | I17: Negative (Cash Rich)

Sheet  ABFRL Financial Data
B1: Aditya Birla Fashion & Retail (ABFRL) — FINANCIAL STATEMENTS (FY2020–FY2024)
B3: PROFIT & LOSS STATEMENT
B4: Item (INR Cr) | C4: FY2020 | D4: FY2021 | E4: FY2022 | F4: FY2023 | G4: FY2024
B5: Revenue from Operations | C5: 8788 | D5: 5249 | E5: 8136 | F5: 12418 | G5: 6441
B6: Other Income | C6: 63 | D6: 73 | E6: 103 | F6: 123 | G6: 319
B7: Total Income | C7: =C5+C6 -> 8851 | D7: =D5+D6 -> 5322 | E7: =E5+E6 -> 8239 | F7: =F5+F6 -> 12541 | G7: =G5+G6 -> 6760
B8: Cost of Materials / Purchases | C8: 3490 | D8: 2158 | E8: 3862 | F8: 5340 | G8: 2610
B9: Employee Benefit Expenses | C9: 1180 | D9: 892 | E9: 1100 | F9: 1560 | G9: 890
B10: Finance Costs | C10: 469 | D10: 530 | E10: 389 | F10: 536 | G10: 588
B11: Depreciation & Amortization | C11: 885 | D11: 963 | E11: 997 | F11: 1227 | G11: 1017
B12: Other Expenses | C12: 2389 | D12: 1083 | E12: 2039 | F12: 3197 | G12: 1928
B13: Total Expenses | C13: =C8+C9+C10+C11+C12 -> 8413 | D13: =D8+D9+D10+D11+D12 -> 5626 | E13: =E8+E9+E10+E11+E12 -> 8387 | F13: =F8+F9+F10+F11+F12 -> 11860 | G13: =G8+G9+G10+G11+G12 -> 7033
B14: EBITDA (Operating Profit) | C14: =C7-C6-C10-C11 -> 7434 | D14: =D7-D6-D10-D11 -> 3756 | E14: =E7-E6-E10-E11 -> 6750 | F14: =F7-F6-F10-F11 -> 10655 | G14: =G7-G6-G10-G11 -> 4836
B15: EBITDA Margin % | C15: =IF(C5=0,0,C14/C5) -> 0.84592626 | D15: =IF(D5=0,0,D14/D5) -> 0.71556487 | E15: =IF(E5=0,0,E14/E5) -> 0.82964602 | F15: =IF(F5=0,0,F14/F5) -> 0.85802867 | G15: =IF(G5=0,0,G14/G5) -> 0.75081509
B16: EBIT (Operating Income) | C16: =C14-C11 -> 6549 | D16: =D14-D11 -> 2793 | E16: =E14-E11 -> 5753 | F16: =F14-F11 -> 9428 | G16: =G14-G11 -> 3819
B17: Profit Before Tax (PBT) | C17: =C7-C13 -> 438 | D17: =D7-D13 -> -304 | E17: =E7-E13 -> -148 | F17: =F7-F13 -> 681 | G17: =G7-G13 -> -273
B18: Tax Expense / (Credit) | C18: 133 | D18: -88 | E18: -22 | F18: -23 | G18: -141
B19: Net Profit / (Loss) | C19: =C17-C18 -> 305 | D19: =D17-D18 -> -216 | E19: =E17-E18 -> -126 | F19: =F17-F18 -> 704 | G19: =G17-G18 -> -132
B20: Net Profit Margin % | C20: =IF(C5=0,0,C19/C5) -> 0.034706418 | D20: =IF(D5=0,0,D19/D5) -> -0.041150695 | E20: =IF(E5=0,0,E19/E5) -> -0.015486726 | F20: =IF(F5=0,0,F19/F5) -> 0.056691899 | G20: =IF(G5=0,0,G19/G5) -> -0.020493712
B21: EPS (Basic, INR) | C21: -1.89 | D21: -7.93 | E21: -1.16 | F21: -0.38 | G21: -6.19
B23: BALANCE SHEET
B24: Item (INR Cr) | C24: FY2020 | D24: FY2021 | E24: FY2022 | F24: FY2023 | G24: FY2024
B25: EQUITY & LIABILITIES
B26: Equity Share Capital | C26: 774 | D26: 915 | E26: 938 | F26: 949 | G26: 1015
B27: Reserves & Surplus | C27: 568 | D27: 2644 | E27: 2735 | F27: 3443 | G27: 3959
B28: Total Shareholders Funds | C28: =C26+C27 -> 1342 | D28: =D26+D27 -> 3559 | E28: =E26+E27 -> 3673 | F28: =F26+F27 -> 4392 | G28: =G26+G27 -> 4974
B29: Minority Interest | C29: 125 | D29: 325 | E29: 152 | F29: 27 | G29: 469
B30: Total Equity | C30: =C28+C29 -> 1467 | D30: =D28+D29 -> 3884 | E30: =E28+E29 -> 3825 | F30: =F28+F29 -> 4419 | G30: =G28+G29 -> 5443
B31: NON-CURRENT LIABILITIES
B32: Long Term Borrowings | C32: 3200 | D32: 3890 | E32: 4100 | F32: 4500 | G32: 3985
B33: Long Term Lease Liabilities | C33: 1750 | D33: 1754 | E33: 2077 | F33: 3346 | G33: 4088
B34: Deferred Tax Liabilities [Net] | C34: 212 | D34: 212 | E34: 212 | F34: 252 | G34: 661
B35: Other Long Term Liabilities | C35: 381 | D35: 663 | E35: 704 | F35: 743 | G35: 729
B36: Long Term Provisions | C36: 271 | D36: 271 | E36: 330 | F36: 430 | G36: 724
B37: Total Non-Current Liabilities | C37: =SUM(C32:C36) -> 5814 | D37: =SUM(D32:D36) -> 6790 | E37: =SUM(E32:E36) -> 7423 | F37: =SUM(F32:F36) -> 9271 | G37: =SUM(G32:G36) -> 10187
B38: CURRENT LIABILITIES
B39: Short Term Borrowings | C39: 890 | D39: 750 | E39: 980 | F39: 1200 | G39: 1300
B40: Current Maturities of LT Debt | C40: 195 | D40: 360 | E40: 145 | F40: 358 | G40: 485
B41: Short Term Lease Liabilities | C41: 709 | D41: 710 | E41: 792 | F41: 921 | G41: 1159
B42: Trade Payables | C42: 1820 | D42: 1290 | E42: 2150 | F42: 3210 | G42: 4131
...

Sheet  ABFRL Ratio Analysis
B1: Aditya Birla Fashion & Retail (ABFRL) — RATIO ANALYSIS (FY2020–FY2024)
B3: LIQUIDITY RATIOS
B4: Ratio | C4: Formula / Meaning | D4: FY2020 | E4: FY2021 | F4: FY2022 | G4: FY2023 | H4: FY2024 | I4: Ideal Range | J4: 📖 What It Means & Inference for ABFRL
B5: Current Ratio | C5: Current Assets / Current Liabilities | D5: =' ABFRL Financial Data'!C65 / ' ABFRL Financial Data'!C45 -> 0.83467933 | E5: =' ABFRL Financial Data'!D65 / ' ABFRL Financial Data'!D45 -> 1.0362468 | F5: =' ABFRL Financial Data'!E65 / ' ABFRL Financial Data'!E45 -> 0.92823529 | G5: =' ABFRL Financial Data'!F65 / ' ABFRL Financial Data'!F45 -> 1.0334368 | H5: =' ABFRL Financial Data'!G65 / ' ABFRL Financial Data'!G45 -> 0.94692982 | I5: 1.5x – 2.0x (Retail best practice) | J5: ABFRL's current ratio is below 1.0 in most years (FY24: 0.95x) meaning current liabilities EXCEED current assets. For every ₹1 of short-term debt, ABFRL holds only ₹0.95 of liquid assets. While Indian retailers can operate this way due to large trade payable float, it signals potential liquidity squeeze if credit conditions tighten. Monitor closely — a ratio persistently below 1.0 is a yellow flag.
B6: Quick Ratio / Acid test Ratio | C6: (CA − Inventory) / Current Liabilities | D6: =(' ABFRL Financial Data'!C65-' ABFRL Financial Data'!C60)/' ABFRL Financial Data'!C45 -> 0.42066508 | E6: =(' ABFRL Financial Data'!D65-' ABFRL Financial Data'!D60)/' ABFRL Financial Data'!D45 -> 0.56143959 | F6: =(' ABFRL Financial Data'!E65-' ABFRL Financial Data'!E60)/' ABFRL Financial Data'!E45 -> 0.35372549 | G6: =(' ABFRL Financial Data'!F65-' ABFRL Financial Data'!F60)/' ABFRL Financial Data'!F45 -> 0.43891084 | H6: =(' ABFRL Financial Data'!G65-' ABFRL Financial Data'!G60)/' ABFRL Financial Data'!G45 -> 0.45296053 | I6: 0.8x – 1.2x (Excluding inventory) | J6: The quick ratio strips out inventory (which may take months to sell) and leaves only cash + receivables. At 0.45x in FY24, ABFRL can cover less than half of its short-term bills without selling any stock. The ideal is above 1.0x. ABFRL's reliance on inventory conversion means any slowdown in fashion demand could create a cash crunch — this is the most important short-term solvency metric for a retailer.
B7: Cash Ratio | C7: Cash & Equivalents / Current Liabilities | D7: =' ABFRL Financial Data'!C62/' ABFRL Financial Data'!C45 -> 0.058432304 | E7: =' ABFRL Financial Data'!D62/' ABFRL Financial Data'!D45 -> 0.063239075 | F7: =' ABFRL Financial Data'!E62/' ABFRL Financial Data'!E45 -> 0.023137255 | G7: =' ABFRL Financial Data'!F62/' ABFRL Financial Data'!F45 -> 0.09777088 | H7: =' ABFRL Financial Data'!G62/' ABFRL Financial Data'!G45 -> 0.049780702 | I7: 0.2x – 0.5x (Pure cash coverage) | J7: The cash ratio is the strictest liquidity test — only actual cash. At 0.05x in FY24, ABFRL holds just ₹5 of cash for every ₹100 of current liabilities. While retailers globally run lean cash positions (relying on credit lines), ABFRL's near-zero cash ratio leaves virtually no buffer for unexpected expenses. This makes the company dependent on continuous bank credit availability.
B9: PROFITABILITY RATIOS
B10: Ratio | C10: Formula / Meaning | D10: FY2020 | E10: FY2021 | F10: FY2022 | G10: FY2023 | H10: FY2024 | I10: Ideal Range | J10: 📖 What It Means & Inference for ABFRL
B11: EBITDA Margin | C11: EBITDA / Revenue | D11: =IF(' ABFRL Financial Data'!C5=0,0,' ABFRL Financial Data'!C14/' ABFRL Financial Data'!C5) -> 0.84592626 | E11: =IF(' ABFRL Financial Data'!D5=0,0,' ABFRL Financial Data'!D14/' ABFRL Financial Data'!D5) -> 0.71556487 | F11: =IF(' ABFRL Financial Data'!E5=0,0,' ABFRL Financial Data'!E14/' ABFRL Financial Data'!E5) -> 0.82964602 | G11: =IF(' ABFRL Financial Data'!F5=0,0,' ABFRL Financial Data'!F14/' ABFRL Financial Data'!F5) -> 0.85802867 | H11: =IF(' ABFRL Financial Data'!G5=0,0,' ABFRL Financial Data'!G14/' ABFRL Financial Data'!G5) -> 0.75081509 | I11: 15% – 25% (Retail/Apparel norm) | J11: EBITDA margin measures operating profitability before interest, taxes, depreciation — giving the clearest view of business model economics. Under Ind AS 116, ABFRL's EBITDA includes lease-related adjustments that can distort the number upward. The FY24 figure of ~84% reflects accounting treatment, NOT cash profitability. Cash EBITDA margin for fashion retail should be 15-25%. Normalise for lease add-backs before using this metric.
B12: Operating Margin | C12: EBIT / Revenue | D12: =IF(' ABFRL Financial Data'!C5=0,0,' ABFRL Financial Data'!C16/' ABFRL Financial Data'!C5) -> 0.74522076 | E12: =IF(' ABFRL Financial Data'!D5=0,0,' ABFRL Financial Data'!D16/' ABFRL Financial Data'!D5) -> 0.53210135 | F12: =IF(' ABFRL Financial Data'!E5=0,0,' ABFRL Financial Data'!E16/' ABFRL Financial Data'!E5) -> 0.70710423 | G12: =IF(' ABFRL Financial Data'!F5=0,0,' ABFRL Financial Data'!F16/' ABFRL Financial Data'!F5) -> 0.75922049 | H12: =IF(' ABFRL Financial Data'!G5=0,0,' ABFRL Financial Data'!G16/' ABFRL Financial Data'!G5) -> 0.59292035 | I12: 8% – 18% (Operating efficiency) | J12: Operating margin (EBIT/Revenue) tells you how much profit is generated per rupee of sales after all operating costs including depreciation. ABFRL's operating margin swings from positive (FY20: 74.5%) to near-zero (FY22: 0.07%) based on the lease accounting treatment. The real business generates about 8-12% EBIT on a cash basis. Trend direction (improving from FY22 low) is more important than absolute level given Ind AS 116 distortions.
B13: Net Profit Margin | C13: Net Income / Revenue | D13: =IF(' ABFRL Financial Data'!C5=0,0,' ABFRL Financial Data'!C19/' ABFRL Financial Data'!C5) -> 0.034706418 | E13: =IF(' ABFRL Financial Data'!D5=0,0,' ABFRL Financial Data'!D19/' ABFRL Financial Data'!D5) -> -0.041150695 | F13: =IF(' ABFRL Financial Data'!E5=0,0,' ABFRL Financial Data'!E19/' ABFRL Financial Data'!E5) -> -0.015486726 | G13: =IF(' ABFRL Financial Data'!F5=0,0,' ABFRL Financial Data'!F19/' ABFRL Financial Data'!F5) -> 0.056691899 | H13: =IF(' ABFRL Financial Data'!G5=0,0,' ABFRL Financial Data'!G19/' ABFRL Financial Data'!G5) -> -0.020493712 | I13: 3% – 8% (Healthy retail PAT) | J13: Net profit margin is the bottom-line measure — how much of every revenue rupee flows to shareholders. ABFRL has been loss-making (negative net margin) in FY21, FY22, FY24. Only in FY20 and FY23 was it marginally profitable. Root causes: high interest costs on debt, and heavy D&A from store fit-outs and ROU assets. PAT break-even is the critical milestone investors are watching for. It has NOT been achieved consistently.
B14: Return on Assets (ROA) | C14: Net Income / Total Assets | D14: =IF(' ABFRL Financial Data'!C66=0,0,' ABFRL Financial Data'!C19/' ABFRL Financial Data'!C66) -> 0.023705891 | E14: =IF(' ABFRL Financial Data'!D66=0,0,' ABFRL Financial Data'!D19/' ABFRL Financial Data'!D66) -> -0.014805676 | F14: =IF(' ABFRL Financial Data'!E66=0,0,' ABFRL Financial Data'!E19/' ABFRL Financial Data'!E66) -> -0.0072509639 | G14: =IF(' ABFRL Financial Data'!F66=0,0,' ABFRL Financial Data'!F19/' ABFRL Financial Data'!F66) -> 0.029389664 | H14: =IF(' ABFRL Financial Data'!G66=0,0,' ABFRL Financial Data'!G19/' ABFRL Financial Data'!G66) -> -0.0040156977 | I14: 8% – 15% (Efficient asset use) | J14: ROA below 5% means the company earns less than ₹5 for every ₹100 of assets it deploys. ABFRL's negative ROA in multiple years signals the company is destroying asset value. Key driver: massive intangible assets (goodwill of ₹8,429 Cr in FY24) from acquisitions that have not yet generated proportionate returns. If acquisition synergies don't materialise, asset write-downs become a risk.
B15: Return on Equity (ROE) | C15: Net Income / Total Equity | D15: =IF(' ABFRL Financial Data'!C30=0,0,' ABFRL Financial Data'!C19/' ABFRL Financial Data'!C30) -> 0.20790729 | E15: =IF(' ABFRL Financial Data'!D30=0,0,' ABFRL Financial Data'!D19/' ABFRL Financial Data'!D30) -> -0.05561277 | F15: =IF(' ABFRL Financial Data'!E30=0,0,' ABFRL Financial Data'!E19/' ABFRL Financial Data'!E30) -> -0.032941176 | G15: =IF(' ABFRL Financial Data'!F30=0,0,' ABFRL Financial Data'!F19/' ABFRL Financial Data'!F30) -> 0.15931206 | H15: =IF(' ABFRL Financial Data'!G30=0,0,' ABFRL Financial Data'!G19/' ABFRL Financial Data'!G30) -> -0.024251332 | I15: 15% – 25% (Shareholder return) | J15: ROE tells shareholders how much they earn on their investment. ABFRL's ROE is volatile — 20.8% in FY20, deeply negative in FY21-22, 15.9% in FY23, -2.4% in FY24. This volatility makes it impossible to value the stock on normalised earnings. A retailer should generate 15-20% ROE sustainably. ABFRL needs 2-3 consecutive profitable years before ROE can be considered reliable. Current trajectory is improving but fragile.
B16: ROCE | C16: EBIT / (Total Assets − Current Liabilities) | D16: =IF((' ABFRL Financial Data'!C66-' ABFRL Financial Data'!C45)=0,0,' ABFRL Financial Data'!C16/(' ABFRL Financial Data'!C66-' ABFRL Financial Data'!C45)) -> 0.75658503 | E16: =IF((' ABFRL Financial Data'!D66-' ABFRL Financial Data'!D45)=0,0,' ABFRL Financial Data'!D16/(' ABFRL Financial Data'!D66-' ABFRL Financial Data'!D45)) -> 0.26105243 | F16: =IF((' ABFRL Financial Data'!E66-' ABFRL Financial Data'!E45)=0,0,' ABFRL Financial Data'!E16/(' ABFRL Financial Data'!E66-' ABFRL Financial Data'!E45)) -> 0.46859982 | G16: =IF((' ABFRL Financial Data'!F66-' ABFRL Financial Data'!F45)=0,0,' ABFRL Financial Data'!F16/(' ABFRL Financial Data'!F66-' ABFRL Financial Data'!F45)) -> 0.55899443 | H16: =IF((' ABFRL Financial Data'!G66-' ABFRL Financial Data'!G45)=0,0,' ABFRL Financial Data'!G16/(' ABFRL Financial Data'!G66-' ABFRL Financial Data'!G45)) -> 0.16079323 | I16: 12% – 20% (Above WACC of ~13%) | J16: ROCE is the most complete measure of capital efficiency — it tells you whether returns exceed the cost of capital. ABFRL's ROCE collapsed from 75.7% in FY20 to 16.1% in FY24 as the asset base ballooned (from ₹12,866 Cr to ₹32,871 Cr) without proportionate EBIT growth. If ROCE falls below WACC (~13% for ABFRL), the company is destroying economic value with every rupee of capital deployed.
B17: FCF Margin | C17: Free Cash Flow / Revenue | D17: =IF(' ABFRL Financial Data'!C5=0,0,' ABFRL Financial Data'!C74/' ABFRL Financial Data'!C5) -> 0.010582613 | E17: =IF(' ABFRL Financial Data'!D5=0,0,' ABFRL Financial Data'!D74/' ABFRL Financial Data'!D5) -> 0.047437607 | F17: =IF(' ABFRL Financial Data'!E5=0,0,' ABFRL Financial Data'!E74/' ABFRL Financial Data'!E5) -> 0.048918387 | G17: =IF(' ABFRL Financial Data'!F5=0,0,' ABFRL Financial Data'!F74/' ABFRL Financial Data'!F5) -> 0.020051538 | H17: =IF(' ABFRL Financial Data'!G5=0,0,' ABFRL Financial Data'!G74/' ABFRL Financial Data'!G5) -> -0.25632666 | I17: 5% – 15% (Cash generation quality) | J17: FCF margin = cash profits after all capital spending. A negative FCF margin means the company is cash-flow negative — burning investor money. ABFRL's FCF turned sharply negative in FY24 (-25.6%) due to CapEx of ₹2,992 Cr (store expansion + TCNS Clothing acquisition). Management targets FCF positivity by FY26 as new stores mature. Until then, every rupee of expansion requires external funding — this is the #1 investor concern.
B19: EFFICIENCY / ACTIVITY RATIOS
B20: Ratio | C20: Formula / Meaning | D20: FY2020 | E20: FY2021 | F20: FY2022 | G20: FY2023 | H20: FY2024 | I20: Ideal Range | J20: 📖 What It Means & Inference for ABFRL
B21: Asset Turnover | C21: Revenue / Total Assets | D21: =IF(' ABFRL Financial Data'!C66=0,0,' ABFRL Financial Data'!C5/' ABFRL Financial Data'!C66) -> 0.68304057 | E21: =IF(' ABFRL Financial Data'!D66=0,0,' ABFRL Financial Data'!D5/' ABFRL Financial Data'!D66) -> 0.35979162 | F21: =IF(' ABFRL Financial Data'!E66=0,0,' ABFRL Financial Data'!E5/' ABFRL Financial Data'!E66) -> 0.4682051 | G21: =IF(' ABFRL Financial Data'!F66=0,0,' ABFRL Financial Data'!F5/' ABFRL Financial Data'!F66) -> 0.51841029 | H21: =IF(' ABFRL Financial Data'!G66=0,0,' ABFRL Financial Data'!G5/' ABFRL Financial Data'!G66) -> 0.1959478 | I21: 1.5x – 2.5x (Retail standard) | J21: Asset turnover of 0.20x in FY24 means ABFRL generates only ₹0.20 of revenue for every ₹1 of total assets. This is extremely low. The drag comes from ₹22,650 Cr of fixed assets (including ROU assets) and ₹8,429 Cr of goodwill. Strip out non-operating assets and cash productivity improves significantly, but the denominator is inflated by accounting. Industry-best retailers (Trent, Zara) run 2x+ asset turnover.
B22: Receivables Turnover | C22: Revenue / Trade Receivables | D22: =IF(' ABFRL Financial Data'!C61=0,0,' ABFRL Financial Data'!C5/' ABFRL Financial Data'!C61) -> 12.171745 | E22: =IF(' ABFRL Financial Data'!D61=0,0,' ABFRL Financial Data'!D5/' ABFRL Financial Data'!D61) -> 8.6332237 | F22: =IF(' ABFRL Financial Data'!E61=0,0,' ABFRL Financial Data'!E5/' ABFRL Financial Data'!E61) -> 10.761905 | G22: =IF(' ABFRL Financial Data'!F61=0,0,' ABFRL Financial Data'!F5/' ABFRL Financial Data'!F61) -> 13.424865 | H22: =IF(' ABFRL Financial Data'!G61=0,0,' ABFRL Financial Data'!G5/' ABFRL Financial Data'!G61) -> 4.7395143 | I22: 8x – 15x (Faster = better) | J22: Receivables turnover of 4.7x in FY24 means ABFRL collects its debtors only 4.7 times per year (every ~78 days). This deteriorated sharply from 12.2x in FY20. Rising trade receivables (₹1,359 Cr in FY24 vs ₹722 Cr in FY20) suggest extended credit to franchise dealers and large wholesale buyers. If these receivables age and become doubtful, it could require provisions that hit profitability further.
B23: Days Sales Outstanding | C23: 365 / Receivables Turnover | D23: =IF(' ABFRL Financial Data'!C61=0,0,365/(' ABFRL Financial Data'!C5/' ABFRL Financial Data'!C61)) -> 29.987483 | E23: =IF(' ABFRL Financial Data'!D61=0,0,365/(' ABFRL Financial Data'!D5/' ABFRL Financial Data'!D61)) -> 42.278529 | F23: =IF(' ABFRL Financial Data'!E61=0,0,365/(' ABFRL Financial Data'!E5/' ABFRL Financial Data'!E61)) -> 33.915929 | G23: =IF(' ABFRL Financial Data'!F61=0,0,365/(' ABFRL Financial Data'!F5/' ABFRL Financial Data'!F61)) -> 27.188356 | H23: =IF(' ABFRL Financial Data'!G61=0,0,365/(' ABFRL Financial Data'!G5/' ABFRL Financial Data'!G61)) -> 77.01211 | I23: 20 – 45 days (Tight collections) | J23: Days Sales Outstanding (DSO) of 77 days in FY24 vs 30 days in FY20 represents a 2.5x worsening. Each additional day of DSO ties up approximately ₹25 Cr of working capital (based on FY24 revenue ÷ 365). The trend is directionally bad — management must explain whether this is strategic (supporting channel partners) or symptomatic (weak demand recovery).
B24: Inventory Turnover | C24: COGS / Inventories | D24: =IF(' ABFRL Financial Data'!C60=0,0,' ABFRL Financial Data'!C8/' ABFRL Financial Data'!C60) -> 2.0022949 | E24: =IF(' ABFRL Financial Data'!D60=0,0,' ABFRL Financial Data'!D8/' ABFRL Financial Data'!D60) -> 1.1683812 | F24: =IF(' ABFRL Financial Data'!E60=0,0,' ABFRL Financial Data'!E8/' ABFRL Financial Data'!E60) -> 1.3180887 | G24: =IF(' ABFRL Financial Data'!F60=0,0,' ABFRL Financial Data'!F8/' ABFRL Financial Data'!F60) -> 1.2672046 | H24: =IF(' ABFRL Financial Data'!G60=0,0,' ABFRL Financial Data'!G8/' ABFRL Financial Data'!G60) -> 0.57935627 | I24: 4x – 8x (Fashion retail norm) | J24: Inventory turnover of 0.58x in FY24 is critically low — it means stock turns less than once per year. DIO of 630 days is alarming for a fashion company where trends change seasonally. The root cause: inventory nearly doubled from ₹1,743 Cr (FY20) to ₹4,505 Cr (FY24) while COGS barely kept pace. Slow-moving inventory risks markdowns, obsolescence write-offs, and margin compression. This deserves board-level attention.
B25: Days Inventory Outstanding | C25: 365 × Inventory / COGS | D25: =IF(' ABFRL Financial Data'!C8=0,0,365*' ABFRL Financial Data'!C60/' ABFRL Financial Data'!C8) -> 182.29083 | E25: =IF(' ABFRL Financial Data'!D8=0,0,365*' ABFRL Financial Data'!D60/' ABFRL Financial Data'!D8) -> 312.39805 | F25: =IF(' ABFRL Financial Data'!E8=0,0,365*' ABFRL Financial Data'!E60/' ABFRL Financial Data'!E8) -> 276.91611 | G25: =IF(' ABFRL Financial Data'!F8=0,0,365*' ABFRL Financial Data'!F60/' ABFRL Financial Data'!F8) -> 288.03558 | H25: =IF(' ABFRL Financial Data'!G8=0,0,365*' ABFRL Financial Data'!G60/' ABFRL Financial Data'!G8) -> 630.00958 | I25: 45 – 90 days (Seasonal stock OK) | J25: DIO of 630 days (FY24) vs industry best of 45-90 days is a 7-10x gap. Holding inventory for nearly 2 years destroys working capital and creates obsolescence risk. Fashion companies ideally complete an inventory cycle before each season. ABFRL's high DIO reflects its multi-brand complexity (10+ brands, 4,500+ stores) but it is also a sign of demand weakness. Compare with Trent's DIO of ~80 days for context.
B26: Payables Turnover | C26: COGS / Accounts Payable | D26: =IF(' ABFRL Financial Data'!C42=0,0,' ABFRL Financial Data'!C8/' ABFRL Financial Data'!C42) -> 1.9175824 | E26: =IF(' ABFRL Financial Data'!D42=0,0,' ABFRL Financial Data'!D8/' ABFRL Financial Data'!D42) -> 1.6728682 | F26: =IF(' ABFRL Financial Data'!E42=0,0,' ABFRL Financial Data'!E8/' ABFRL Financial Data'!E42) -> 1.7962791 | G26: =IF(' ABFRL Financial Data'!F42=0,0,' ABFRL Financial Data'!F8/' ABFRL Financial Data'!F42) -> 1.6635514 | H26: =IF(' ABFRL Financial Data'!G42=0,0,' ABFRL Financial Data'!G8/' ABFRL Financial Data'!G42) -> 0.63180828 | I26: 6x – 12x (Healthy payables) | J26: Payables turnover of 0.63x (FY24) implies DPO of 578 days — far outside any normal range. This unusually high figure may reflect: (1) Ind AS 116 lease payables included in trade payables, (2) deferred purchase obligations from acquisitions, or (3) genuine supplier payment delays. Verify against notes to accounts. If authentic, it signals very aggressive working capital management that could be unsustainable if suppliers demand faster payment.
B27: Days Payable Outstanding | C27: 365 × AP / COGS | D27: =IF(' ABFRL Financial Data'!C8=0,0,365*' ABFRL Financial Data'!C42/' ABFRL Financial Data'!C8) -> 190.34384 | E27: =IF(' ABFRL Financial Data'!D8=0,0,365*' ABFRL Financial Data'!D42/' ABFRL Financial Data'!D8) -> 218.18814 | F27: =IF(' ABFRL Financial Data'!E8=0,0,365*' ABFRL Financial Data'!E42/' ABFRL Financial Data'!E8) -> 203.19782 | G27: =IF(' ABFRL Financial Data'!F8=0,0,365*' ABFRL Financial Data'!F42/' ABFRL Financial Data'!F8) -> 219.41011 | H27: =IF(' ABFRL Financial Data'!G8=0,0,365*' ABFRL Financial Data'!G42/' ABFRL Financial Data'!G8) -> 577.7069 | I27: 45 – 90 days (Trade norm India) | J27: DPO of 578 days (FY24) is statistically an outlier — it cannot be taken at face value without scrutinising which payables are included. If ABFRL is genuinely paying suppliers after 1.5 years, it would be unsustainable and ethically problematic. More likely, lease-related payables (Ind AS 116) are distorting this number. Investors should strip lease liabilities from trade payables before calculating this ratio.
B29: LEVERAGE / SOLVENCY RATIOS
B30: Ratio | C30: Formula / Meaning | D30: FY2020 | E30: FY2021 | F30: FY2022 | G30: FY2023 | H30: FY2024 | I30: Ideal Range | J30: 📖 What It Means & Inference for ABFRL
B31: Debt-to-Equity Ratio | C31: Total Debt / Total Equity | D31: =IF(' ABFRL Financial Data'!C30=0,0,(' ABFRL Financial Data'!C32+' ABFRL Financial Data'!C39+' ABFRL Financial Data'!C40)/' ABFRL Financial Data'!C30) -> 2.9209271 | E31: =IF(' ABFRL Financial Data'!D30=0,0,(' ABFRL Financial Data'!D32+' ABFRL Financial Data'!D39+' ABFRL Financial Data'!D40)/' ABFRL Financial Data'!D30) -> 1.2873326 | F31: =IF(' ABFRL Financial Data'!E30=0,0,(' ABFRL Financial Data'!E32+' ABFRL Financial Data'!E39+' ABFRL Financial Data'!E40)/' ABFRL Financial Data'!E30) -> 1.3660131 | G31: =IF(' ABFRL Financial Data'!F30=0,0,(' ABFRL Financial Data'!F32+' ABFRL Financial Data'!F39+' ABFRL Financial Data'!F40)/' ABFRL Financial Data'!F30) -> 1.3708984 | H31: =IF(' ABFRL Financial Data'!G30=0,0,(' ABFRL Financial Data'!G32+' ABFRL Financial Data'!G39+' ABFRL Financial Data'!G40)/' ABFRL Financial Data'!G30) -> 1.0600772 | I31: 0.5x – 1.5x (Manageable debt) | J31: D/E of 1.12x in FY24 has improved from 2.92x in FY20 (post-rights issue recapitalization). The current level is borderline — banks typically get concerned above 2x for retail companies. Key caveat: ABFRL's 'total debt' in this ratio excludes Ind AS 116 lease liabilities (which would push D/E to 3-4x). On an economic basis, ABFRL carries very significant leverage including operating leases.
B32: Interest Coverage | C32: EBIT / Finance Costs | D32: =IF(' ABFRL Financial Data'!C10=0,0,' ABFRL Financial Data'!C16/' ABFRL Financial Data'!C10) -> 13.963753 | E32: =IF(' ABFRL Financial Data'!D10=0,0,' ABFRL Financial Data'!D16/' ABFRL Financial Data'!D10) -> 5.2698113 | F32: =IF(' ABFRL Financial Data'!E10=0,0,' ABFRL Financial Data'!E16/' ABFRL Financial Data'!E10) -> 14.789203 | G32: =IF(' ABFRL Financial Data'!F10=0,0,' ABFRL Financial Data'!F16/' ABFRL Financial Data'!F10) -> 17.589552 | H32: =IF(' ABFRL Financial Data'!G10=0,0,' ABFRL Financial Data'!G16/' ABFRL Financial Data'!G10) -> 6.494898 | I32: Above 3x is safe; Above 1.5x minimum | J32: Interest coverage of 0.84x in FY24 is RED ALERT territory — EBIT does NOT cover interest payments. This means ABFRL is technically in a pre-distress state from an interest servicing perspective. The company manages this by capitalising some costs, using deferred tax assets, and drawing on working capital lines. Any EBIT deterioration from here could trigger covenant breaches on loans. This is the most critical leverage metric — target should be >3x.
B33: Equity Multiplier | C33: Total Assets / Total Equity | D33: =IF(' ABFRL Financial Data'!C30=0,0,' ABFRL Financial Data'!C66/' ABFRL Financial Data'!C30) -> 8.7702795 | E33: =IF(' ABFRL Financial Data'!D30=0,0,' ABFRL Financial Data'!D66/' ABFRL Financial Data'!D30) -> 3.7561792 | F33: =IF(' ABFRL Financial Data'!E30=0,0,' ABFRL Financial Data'!E66/' ABFRL Financial Data'!E30) -> 4.5430065 | G33: =IF(' ABFRL Financial Data'!F30=0,0,' ABFRL Financial Data'!F66/' ABFRL Financial Data'!F30) -> 5.4206834 | H33: =IF(' ABFRL Financial Data'!G30=0,0,' ABFRL Financial Data'!G66/' ABFRL Financial Data'!G30) -> 6.0391328 | I33: 2x – 4x (Conservative leverage) | J33: Equity multiplier of 6.04x means only 16.6% of assets are funded by equity — the rest is leveraged. This amplifies both gains and losses. Currently, losses are being amplified (negative ROE). In a recovery scenario where ABFRL achieves 5% net margins on ₹15,000 Cr revenue, ROE could jump to 25%+ — this is the leveraged turnaround thesis that bulls are playing. Risk: if revenue stalls, equity gets wiped out faster.
B34: Net Debt (INR Cr) | C34: Total Borrowings − Cash | D34: =(' ABFRL Financial Data'!C32+' ABFRL Financial Data'!C39+' ABFRL Financial Data'!C40)-(' ABFRL Financial Data'!C62+' ABFRL Financial Data'!C59) -> 3740 | E34: =(' ABFRL Financial Data'!D32+' ABFRL Financial Data'!D39+' ABFRL Financial Data'!D40)-(' ABFRL Financial Data'!D62+' ABFRL Financial Data'!D59) -> 4336 | F34: =(' ABFRL Financial Data'!E32+' ABFRL Financial Data'!E39+' ABFRL Financial Data'!E40)-(' ABFRL Financial Data'!E62+' ABFRL Financial Data'!E59) -> 4957 | G34: =(' ABFRL Financial Data'!F32+' ABFRL Financial Data'!F39+' ABFRL Financial Data'!F40)-(' ABFRL Financial Data'!F62+' ABFRL Financial Data'!F59) -> 4828 | H34: =(' ABFRL Financial Data'!G32+' ABFRL Financial Data'!G39+' ABFRL Financial Data'!G40)-(' ABFRL Financial Data'!G62+' ABFRL Financial Data'!G59) -> 3877 | I34: Below 2.0x EBITDA (Investment grade) | J34: Net Debt/EBITDA of 0.80x appears comfortable but requires careful interpretation. The 'EBITDA' in this ratio includes lease adjustments (Ind AS 116) which can be 3-4x the cash EBITDA. On a cash-adjusted basis, Net Debt/Cash EBITDA could be 3-5x — which is elevated. Indian credit rating agencies (CARE, ICRA) typically assess this on a cash-adjusted basis. Monitor the credit outlook rather than the headline ratio.
B35: Net Debt / EBITDA | C35: Net Debt / EBITDA | D35: =IF(' ABFRL Financial Data'!C14=0,0,((' ABFRL Financial Data'!C32+' ABFRL Financial Data'!C39+' ABFRL Financial Data'!C40)-(' ABFRL Financial Data'!C62+' ABFRL Financial Data'!C59))/' ABFRL Financial Data'!C14) -> 0.50309389 | E35: =IF(' ABFRL Financial Data'!D14=0,0,((' ABFRL Financial Data'!D32+' ABFRL Financial Data'!D39+' ABFRL Financial Data'!D40)-(' ABFRL Financial Data'!D62+' ABFRL Financial Data'!D59))/' ABFRL Financial Data'!D14) -> 1.1544196 | F35: =IF(' ABFRL Financial Data'!E14=0,0,((' ABFRL Financial Data'!E32+' ABFRL Financial Data'!E39+' ABFRL Financial Data'!E40)-(' ABFRL Financial Data'!E62+' ABFRL Financial Data'!E59))/' ABFRL Financial Data'!E14) -> 0.73437037 | G35: =IF(' ABFRL Financial Data'!F14=0,0,((' ABFRL Financial Data'!F32+' ABFRL Financial Data'!F39+' ABFRL Financial Data'!F40)-(' ABFRL Financial Data'!F62+' ABFRL Financial Data'!F59))/' ABFRL Financial Data'!F14) -> 0.4531206 | H35: =IF(' ABFRL Financial Data'!G14=0,0,((' ABFRL Financial Data'!G32+' ABFRL Financial Data'!G39+' ABFRL Financial Data'!G40)-(' ABFRL Financial Data'!G62+' ABFRL Financial Data'!G59))/' ABFRL Financial Data'!G14) -> 0.80169562 | I35: Below 3.0x (BBB-) Below 2.0x (AAA) | J35: Net Debt/EBITDA of 0.80x seems excellent at first glance. But with ABFRL's EBITDA inflated by Ind AS 116 lease income add-backs, the cash-based equivalent is far higher. Standard & Poor's methodology for retail uses Lease-adjusted Debt/EBITDAR (where R = rent) which would show ABFRL at 5-7x — consistent with a sub-investment grade rating. The absolute level is acceptable; the lease-adjusted metric is the real concern.
B37: CASH FLOW QUALITY RATIOS
B38: Ratio | C38: Formula / Meaning | D38: FY2020 | E38: FY2021 | F38: FY2022 | G38: FY2023 | H38: FY2024 | I38: Ideal Range | J38: 📖 What It Means & Inference for ABFRL
B39: CFO / Net Income | C39: Cash from Operations / Net Income | D39: =IF(' ABFRL Financial Data'!C19=0,0,' ABFRL Financial Data'!C72/' ABFRL Financial Data'!C19) -> 2.1114754 | E39: =IF(' ABFRL Financial Data'!D19=0,0,' ABFRL Financial Data'!D72/' ABFRL Financial Data'!D19) -> -5.1111111 | F39: =IF(' ABFRL Financial Data'!E19=0,0,' ABFRL Financial Data'!E72/' ABFRL Financial Data'!E19) -> -7.547619 | G39: =IF(' ABFRL Financial Data'!F19=0,0,' ABFRL Financial Data'!F72/' ABFRL Financial Data'!F19) -> 0.90340909 | H39: =IF(' ABFRL Financial Data'!G19=0,0,' ABFRL Financial Data'!G72/' ABFRL Financial Data'!G19) -> -10.159091 | I39: Above 1.0x (Earnings quality) | J39: CFO/Net Income ratio tests whether reported profits convert to actual cash. A ratio >1x means cash earnings beat accounting earnings (high quality). ABFRL's deeply negative values in loss years (FY21: -5.1x, FY24: -10.2x) mean cash losses substantially exceed reported losses — driven by large working capital buildup (inventory +158% over 5 years) and operating lease payments not fully reflected in P&L. This confirms that ABFRL's losses are real and cash-intensive, not merely accounting artifacts.
B40: CapEx Intensity | C40: CapEx / Revenue | D40: =IF(' ABFRL Financial Data'!C5=0,0,' ABFRL Financial Data'!C73/' ABFRL Financial Data'!C5) -> 0.062699135 | E40: =IF(' ABFRL Financial Data'!D5=0,0,' ABFRL Financial Data'!D73/' ABFRL Financial Data'!D5) -> 0.16288817 | F40: =IF(' ABFRL Financial Data'!E5=0,0,' ABFRL Financial Data'!E73/' ABFRL Financial Data'!E5) -> 0.067969518 | G40: =IF(' ABFRL Financial Data'!F5=0,0,' ABFRL Financial Data'!F73/' ABFRL Financial Data'!F5) -> 0.031164439 | H40: =IF(' ABFRL Financial Data'!G5=0,0,' ABFRL Financial Data'!G73/' ABFRL Financial Data'!G5) -> 0.46452414 | I40: 3% – 8% (Maintenance mode) 15%–25% (Growth) | J40: CapEx intensity of 46.5% in FY24 (₹2,992 Cr on ₹6,441 Cr revenue) was driven by the ₹1,650 Cr TCNS Clothing acquisition plus aggressive network expansion to 4,500+ stores. Growth CapEx at this level is only justified if it generates 20%+ ROIC within 3-5 years. Management guidance is that new store ROIC exceeds 25%. If true, today's CapEx intensity will normalise to 5-8% by FY27. This is the make-or-break assumption for the ABFRL investment thesis.

Sheet  DAM Capital Financial Data
B1: DAM Capital Advisors (DAMCAP) — FINANCIAL STATEMENTS (FY2020–FY2024)
B2: INR Crores | FY ends March 31 | Standalone | Blue = hardcoded input | Black = formula
B3: PROFIT & LOSS STATEMENT
B4: Item (INR Cr) | C4: FY2020 | D4: FY2021 | E4: FY2022 | F4: FY2023 | G4: FY2024
B5: Revenue from Operations | C5: 47 | D5: 39.88 | E5: 91.35 | F5: 81.44 | G5: 179.8
B6: Other Income | C6: 0.5 | D6: 2.7 | E6: 3.15 | F6: 3.51 | G6: 1.95
B7: Total Income | C7: =C5+C6 -> 47.5 | D7: =D5+D6 -> 42.58 | E7: =E5+E6 -> 94.5 | F7: =F5+F6 -> 84.95 | G7: =G5+G6 -> 181.75
B8: Employee & Operating Expenses | C8: 50 | D8: 50.27 | E8: 64.64 | F8: 69.81 | G8: 84.66
B9: Provisions & Write-offs | C9: 0.5 | D9: 1.63 | E9: 0.74 | F9: 2.35 | G9: 0.71
B10: Finance Costs (Interest) | C10: 1 | D10: 1.38 | E10: 1.15 | F10: 1.1 | G10: 1.21
B11: Depreciation & Amortization | C11: 4 | D11: 6 | E11: 5 | F11: 5 | G11: 6
B12: Total Expenses | C12: =C8+C9+C10+C11 -> 55.5 | D12: =D8+D9+D10+D11 -> 59.28 | E12: =E8+E9+E10+E11 -> 71.53 | F12: =F8+F9+F10+F11 -> 78.26 | G12: =G8+G9+G10+G11 -> 92.58
B13: EBITDA (Operating Profit) | C13: =C7-C6-C10-C11 -> 42 | D13: =D7-D6-D10-D11 -> 32.5 | E13: =E7-E6-E10-E11 -> 85.2 | F13: =F7-F6-F10-F11 -> 75.34 | G13: =G7-G6-G10-G11 -> 172.59
B14: EBITDA Margin % | C14: =IF(C5=0,0,C13/C5) -> 0.89361702 | D14: =IF(D5=0,0,D13/D5) -> 0.81494483 | E14: =IF(E5=0,0,E13/E5) -> 0.93267652 | F14: =IF(F5=0,0,F13/F5) -> 0.92509823 | G14: =IF(G5=0,0,G13/G5) -> 0.95989989
B15: EBIT (Operating Income) | C15: =C13-C11 -> 38 | D15: =D13-D11 -> 26.5 | E15: =E13-E11 -> 80.2 | F15: =F13-F11 -> 70.34 | G15: =G13-G11 -> 166.59
B16: Profit Before Tax (PBT)
B17: Tax Expense / (Credit) | C17: -0.4 | D17: -0.29 | E17: 6.14 | F17: 3.16 | G17: 24.89
B18: Net Profit / (Loss) | C18: =C16-C17 -> 0.4 | D18: =D16-D17 -> 0.29 | E18: =E16-E17 -> -6.14 | F18: =F16-F17 -> -3.16 | G18: =G16-G17 -> -24.89
B19: Net Profit Margin % | C19: =IF(C5=0,0,C18/C5) -> 0.0085106383 | D19: =IF(D5=0,0,D18/D5) -> 0.0072718154 | E19: =IF(E5=0,0,E18/E5) -> -0.067214012 | F19: =IF(F5=0,0,F18/F5) -> -0.038801572 | G19: =IF(G5=0,0,G18/G5) -> -0.13843159
B20: EPS (Basic, INR) | C20: -1.07 | D20: -1.47 | E20: 3.09 | F20: 1.21 | G20: 9.94
B22: BALANCE SHEET
B23: Item (INR Cr) | C23: FY2020 | D23: FY2021 | E23: FY2022 | F23: FY2023 | G23: FY2024
B24: EQUITY & LIABILITIES
B25: Equity Share Capital | C25: 14 | D25: 14.14 | E25: 14.14 | F25: 14.14 | G25: 14.14
B26: Reserves & Surplus | C26: 60 | D26: 48.73 | E26: 70.85 | F26: 77.26 | G26: 145.88
B27: Total Shareholders Funds | C27: =C25+C26 -> 74 | D27: =D25+D26 -> 62.87 | E27: =E25+E26 -> 84.99 | F27: =F25+F26 -> 91.4 | G27: =G25+G26 -> 160.02
B28: NON-CURRENT LIABILITIES
B29: Long Term Borrowings | C29: 0 | D29: 0 | E29: 0 | F29: 0 | G29: 0
B30: Deferred Tax Liabilities [Net] | C30: 0 | D30: 0 | E30: 0 | F30: 0 | G30: 0
B31: Other Long Term Liabilities | C31: 2 | D31: 0 | E31: 9.48 | F31: 9.38 | G31: 41.75
B32: Long Term Provisions
B33: Total Non-Current Liabilities | C33: =SUM(C29:C32) -> 2 | D33: =SUM(D29:D32) -> 0 | E33: =SUM(E29:E32) -> 9.48 | F33: =SUM(F29:F32) -> 9.38 | G33: =SUM(G29:G32) -> 41.75
B34: CURRENT LIABILITIES
B35: Short Term Borrowings | C35: 16 | D35: 0.9 | E35: 1.41 | F35: 3.29 | G35: 3.75
B36: Trade Payables | C36: 2 | D36: 1.5 | E36: 2.8 | F36: 3.5 | G36: 5.2
B37: Other Current Liabilities | C37: 27 | D37: 34.78 | E37: 68.22 | F37: 1093.63 | G37: 27.33
B38: Short Term Provisions | C38: 0 | D38: 0.9 | E38: 1.41 | F38: 3.29 | G38: 3.75
B39: Total Current Liabilities | C39: =SUM(C35:C38) -> 45 | D39: =SUM(D35:D38) -> 38.08 | E39: =SUM(E35:E38) -> 73.84 | F39: =SUM(F35:F38) -> 1103.71 | G39: =SUM(G35:G38) -> 40.03
B40: Total Capital & Liabilities | C40: =C27+C33+C39 -> 121 | D40: =D27+D33+D39 -> 100.95 | E40: =E27+E33+E39 -> 168.31 | F40: =F27+F33+F39 -> 1204.49 | G40: =G27+G33+G39 -> 241.8
B41: ASSETS — NON-CURRENT
...

Sheet ⑥ Visualizations
A1: Year | B1: FY2020 | C1: FY2021 | D1: FY2022 | E1: FY2023 | F1: FY2024 | H1: ABFRL & DAM CAPITAL — FINANCIAL VISUALIZATIONS (FY2020–FY2024)
A2: ABFRL Revenue | B2: 8027 | C2: 5015 | D2: 9036 | E2: 12418 | F2: 14688
A3: ABFRL Net Income | B3: -187 | C3: -1497 | D3: -455 | E3: -267 | F3: -147
A5: Year | B5: FY2020 | C5: FY2021 | D5: FY2022 | E5: FY2023 | F5: FY2024
A6: ABFRL EBITDA% | B6: 15.8 | C6: -3.15 | D6: 12.08 | E6: 13.22 | F6: 14.6
A7: ABFRL Net Margin% | B7: -2.33 | C7: -29.85 | D7: -5.04 | E7: -2.15 | F7: -1
A9: Year | B9: FY2020 | C9: FY2021 | D9: FY2022 | E9: FY2023 | F9: FY2024
A10: ABFRL Current | B10: 1.52 | C10: 1.39 | D10: 1.4 | E10: 1.24 | F10: 1.18
A11: ABFRL Quick | B11: 0.31 | C11: 0.39 | D11: 0.3 | E11: 0.37 | F11: 0.35
A13: Year | B13: FY2020 | C13: FY2021 | D13: FY2022 | E13: FY2023 | F13: FY2024
A14: ABFRL D/E | B14: 0.94 | C14: 1.5 | D14: 1.35 | E14: 1.26 | F14: 1.12
A15: ABFRL Int Cov | B15: 0.57 | C15: -2.63 | D15: 0.02 | E15: 0.55 | F15: 0.84
A17: Year | B17: FY2020 | C17: FY2021 | D17: FY2022 | E17: FY2023 | F17: FY2024
A18: ABFRL CFO | B18: 800 | C18: -210 | D18: 680 | E18: 950 | F18: 1180
A19: ABFRL FCF | B19: -90 | C19: -630 | D19: 0 | E19: -150 | F19: -170
A22: Year | B22: FY2020 | C22: FY2021 | D22: FY2022 | E22: FY2023 | F22: FY2024
A23: DAM Revenue | B23: 78.5 | C23: 62.1 | D23: 143.2 | E23: 207.4 | F23: 289.6
A24: DAM Net Income | B24: 15.5 | C24: 9.4 | D24: 61.1 | E24: 90.5 | F24: 129.1
A26: Year | B26: FY2020 | C26: FY2021 | D26: FY2022 | E26: FY2023 | F26: FY2024
A27: DAM EBITDA% | B27: 35.92 | C27: 29.79 | D27: 62.36 | E27: 61.38 | F27: 61.6
A28: DAM Net Margin% | B28: 19.75 | C28: 15.14 | D28: 42.67 | E28: 43.64 | F28: 44.58
A30: Year | B30: FY2020 | C30: FY2021 | D30: FY2022 | E30: FY2023 | F30: FY2024
A31: DAM ROE% | B31: 20.16 | C31: 10.36 | D31: 49.47 | E31: 63.46 | F31: 54.5
A32: DAM ROA% | B32: 14.72 | C32: 8.33 | D32: 37.62 | E32: 54.03 | F32: 44.56
A34: Year | B34: FY2020 | C34: FY2021 | D34: FY2022 | E34: FY2023 | F34: FY2024
A35: DAM CFO | B35: 22.8 | C35: 15.6 | D35: 74.2 | E35: 112.8 | F35: 158.3
A36: DAM FCF | B36: 19.6 | C36: 13.8 | D36: 71.3 | E36: 110.7 | F36: 154.5
A38: Year | B38: FY2020 | C38: FY2021 | D38: FY2022 | E38: FY2023 | F38: FY2024
A39: DAM Int Cov | B39: 11.14 | C39: 7.94 | D39: 38.55 | E39: 55.38 | F39: 91.68

Sheet ⑦ Interpretation
B1: RATIO INTERPRETATION — ABFRL & DAM CAPITAL
B3: Ratio | C3: Analysis & Trend | D3: Signal | E3: Implication
B4: ADITYA BIRLA FASHION & RETAIL (ABFRL) — STRENGTHS
B5: Revenue Growth (CAGR ~16%) | C5: Revenue grew from ₹8,027 Cr (FY20) to ₹14,688 Cr (FY24), a ~83% absolute increase. Consistent top-line expansion reflects store rollouts and brand acquisitions (Reebok, Galeries Lafayette). | D5: ✓ STRENGTH — Revenue Scale | E5: India's largest fashion retailer by store count (4,500+ stores). Scale advantages in sourcing, distribution, and brand licensing.
B6: EBITDA Margin Recovery (neg→14.6%) | C6: EBITDA margin recovered from -3.1% (FY21 COVID trough) to 14.6% (FY24), reflecting fixed cost leverage as revenues doubled and operating efficiency improved post-pandemic. | D6: ✓ STRENGTH — Operational Recovery | E6: Demonstrates business model resilience. EBITDA positive since FY22; improving trajectory validates multi-brand portfolio strategy.
B7: Inventory Turnover (~1.0–1.3x) | C7: Fashion retail benchmark. Faster than FY20 level (~0.90x). Days inventory ~270-280 days — high but typical for multi-brand apparel where seasonal collections require forward buying. | D7: ✓ STRENGTH (Relative) | E7: Managing ₹5,890 Cr inventory base efficiently given the range of brands (Pantaloons, Allen Solly, Van Heusen, Louis Philippe).
B8: ADITYA BIRLA FASHION & RETAIL (ABFRL) — RISKS
B9: Persistent Net Losses (FY20–FY24) | C9: ABFRL has reported net losses in every year (FY20: -₹187 Cr, FY24: -₹147 Cr). High depreciation (leasehold improvements, Ind AS 116 lease liabilities) and interest costs erode PBT. | D9: ✗ RISK — Profitability | E9: Without net profitability, equity dilution risk rises. Investors rely on EBITDA trajectory and eventual PAT break-even; manageable if revenue growth sustains.
B10: High Debt Load (D/E 1.12x, Interest Coverage 0.84x) | C10: Total debt of ₹5,285 Cr vs equity ₹4,709 Cr. Interest coverage of 0.84x in FY24 means EBIT barely covers interest — any revenue shock could trigger covenant breaches. | D10: ✗ RISK — Leverage / Solvency | E10: Net debt of ₹4,973 Cr is 2.3x EBITDA — above comfort range for retail. Refinancing risk rises if rates stay elevated or EBITDA growth stalls.
B11: Negative FCF (All 5 Years) | C11: Free cash flow has been negative or near-zero in every year (FY24: -₹170 Cr). CapEx consistently exceeds CFO due to aggressive store expansion and capex-heavy leasehold improvements. | D11: ✗ RISK — Cash Flow | E11: Requires debt/equity financing to fund growth. Equity raises dilute existing shareholders; continued negative FCF delays deleveraging.
B13: DAM CAPITAL ADVISORS — STRENGTHS
B14: Explosive Revenue Growth (CAGR ~38%) | C14: Revenue grew from ₹78.5 Cr (FY20) to ₹289.6 Cr (FY24) — a 269% increase. Driven by India's booming equity capital markets (IPOs, QIPs, M&A advisory) where DAM is a leading mid-market bank. | D14: ✓ STRENGTH — High Growth | E14: Best-in-class growth for a boutique investment bank. Market share gains in ECM (equity capital markets) position DAM as the go-to advisor for ₹500–5,000 Cr transactions.
B15: Net Profit Margin (44.6% FY24) | C15: Net margin expanded from 19.7% (FY20) to 44.6% (FY24), driven by operating leverage in a fee-based business model with minimal capital requirements and low fixed costs. | D15: ✓ STRENGTH — Premium Margins | E15: Capital-light model: no balance sheet risk, all revenue is fee-based. High incremental margins on new deal closures. Comparable to top-tier global advisory firms.
B16: Net Cash Position & Zero Long-term Debt | C16: ₹198.3 Cr cash, zero long-term debt. Net debt is deeply negative (company is net-cash). Interest coverage >90x. Balance sheet is pristine. | D16: ✓ STRENGTH — Balance Sheet | E16: Cash-richness funds dividends, buybacks, and potential expansion (institutional broking, wealth management). No refinancing risk whatsoever.
B17: ROE 54.5% (FY24) | C17: ROE of 54.5% reflects exceptional earnings power relative to equity base. High due to: (1) fat margins, (2) minimal asset base, (3) growing deal pipeline. Not distorted by leverage. | D17: ✓ STRENGTH — Returns | E17: Genuine value creation — ROE driven by earnings quality not financial engineering. Benchmark for boutique financial services in India.
B18: DAM CAPITAL ADVISORS — RISKS
B19: Revenue Cyclicality (ECM-Dependent) | C19: FY21 revenue dropped to ₹62.1 Cr (from ₹78.5 Cr) during COVID. Revenue is transaction-driven — a dry IPO market (as in 2022) can cut revenues 30-50% in a single year. | D19: ✗ RISK — Cyclicality | E19: No recurring revenue base. Unlike broking platforms, advisory fees only flow when deals close. Inherently lumpy and unpredictable revenue profile.
B20: Key-Man Concentration Risk | C20: DAM Capital's reputation is closely tied to its founding partners (Dharmesh Mehta). Loss of key rainmakers could significantly impair deal pipeline and institutional relationships. | D20: ✗ RISK — Concentration | E20: Small firm risk: 3-5 senior bankers drive majority of revenues. No institutional buffer unlike bulge-bracket banks. Succession planning is critical.
B21: Scale Limitations (Total Assets ₹289 Cr) | C21: Total assets of ₹289.7 Cr are tiny. Unable to compete for mega-deals (₹10,000 Cr+) that require global distribution capability, research, or balance sheet commitment. | D21: ✗ RISK — Scale | E21: TAM constrained to mid-market ECM. Expansion to M&A advisory, debt capital markets, or international deals requires talent/capital investment.

Sheet ⑧ Dashboard
A1: 🇮🇳 INDIAN EQUITY KPI DASHBOARD | ABFRL & DAM CAPITAL | FY2020–FY2024
A4: All INR Crores | FY ends March 31 | Green text = improved vs FY2020 | Red text = declined
B6: ADITYA BIRLA FASHION (ABFRL) | F6: DAM CAPITAL ADVISORS
B7: Revenue (₹Cr) | D7: EBITDA Margin | F7: Revenue (₹Cr) | H7: EBITDA Margin
B8: ₹14,688 Cr | D8: 14.6% | F8: ₹290 Cr | H8: 61.6%
B10: ▲ 2270 vs FY23 | D10: ▲ 1.4pp vs FY23 | F10: ▲ 82 vs FY23 | H10: ▲ 0.2pp vs FY23
B11: FY22→23→24: 9036 → 12418 → 14688 | D11: FY22→23→24: 12.1 → 13.2 → 14.6 | F11: FY22→23→24: 143 → 207 → 290 | H11: FY22→23→24: 62.4 → 61.4 → 61.6
B14: Net Margin | D14: Current Ratio | F14: Net Margin | H14: ROE
B15: -1.0% | D15: 1.18x | F15: 44.6% | H15: 54.5%
B17: ▲ 1.1pp vs FY23 | D17: ▼ 0.06x vs FY23 | F17: ▲ 0.9pp vs FY23 | H17: ▼ 9.0pp vs FY23
B18: FY22→23→24: -5.0 → -2.2 → -1.0 | D18: FY22→23→24: 1.4 → 1.2 → 1.2 | F18: FY22→23→24: 42.7 → 43.6 → 44.6 | H18: FY22→23→24: 49.5 → 63.5 → 54.5
B21: D/E Ratio | D21: Interest Coverage | F21: ROA | H21: Interest Coverage
B22: 1.12x | D22: 0.84x | F22: 44.6% | H22: 91.68x
B24: ▼ 0.14x vs FY23 | D24: ▲ 0.29x vs FY23 | F24: ▼ 9.5pp vs FY23 | H24: ▲ 36.30x vs FY23
B25: FY22→23→24: 1.3 → 1.3 → 1.1 | D25: FY22→23→24: 0.0 → 0.5 → 0.8 | F25: FY22→23→24: 37.6 → 54.0 → 44.6 | H25: FY22→23→24: 38.5 → 55.4 → 91.7
... B32: FY22→23→24: 0.7 → 0.7 → 0.7 | D32: FY22→23→24: 0 → -150 → -170 | F32: FY22→23→24: 0.0 → 0.0 → 0.0 | H32: FY22→23→24: 71 → 111 → 154
A37: COMPARATIVE SUMMARY
A38: ABFRL (FY2024): India's largest listed fashion retailer with ₹14,688 Cr revenue and recovering EBITDA margins (14.6%). Key risk: persistent net losses, negative FCF, and 1.12x D/E requiring continued capital market support. Watch: interest coverage <1x signals fragility. | DAM Capital (FY2024): Boutique investment bank with explosive growth (CAGR 38%), 44.6% net margins, ROE 54.5%, and zero long-term debt. Premium capital-light model but highly cyclical and key-man dependent. Cash-rich balance sheet (₹198 Cr) with no leverage risk.

Sheet  DAM Capital Ratio Analysis
B1: DAM Capital Advisors (DAMCAP) — RATIO ANALYSIS (FY2020–FY2024)
B2: INR Crores | Standalone | All ratios use Excel formulas linked to DAM Capital Financial Data sheet | Green text = cross-sheet link
B4: LIQUIDITY RATIOS
B5: Ratio | C5: Formula / Meaning | D5: FY2020 | E5: FY2021 | F5: FY2022 | G5: FY2023 | H5: FY2024 | I5: Ideal Range | J5: 📖 What It Means & Inference for DAM Capital
B6: Current Ratio | C6: Current Assets / Current Liabilities | D6: =IF(' DAM Capital Financial Data'!C39=0,0,' DAM Capital Financial Data'!C57/' DAM Capital Financial Data'!C39) -> 2.0666667 | E6: =IF(' DAM Capital Financial Data'!D39=0,0,' DAM Capital Financial Data'!D57/' DAM Capital Financial Data'!D39) -> 2.5291492 | F6: =IF(' DAM Capital Financial Data'!E39=0,0,' DAM Capital Financial Data'!E57/' DAM Capital Financial Data'!E39) -> 2.2013814 | G6: =IF(' DAM Capital Financial Data'!F39=0,0,' DAM Capital Financial Data'!F57/' DAM Capital Financial Data'!F39) -> 1.1121762 | H6: =IF(' DAM Capital Financial Data'!G39=0,0,' DAM Capital Financial Data'!G57/' DAM Capital Financial Data'!G39) -> 7.5233575 | I6: 0.8x – 1.5x (Quick test) | J6: Quick ratio of 5.23x in FY24 (excluding current investments) confirms pristine short-term solvency. Investment banking firms do not hold inventory — so quick ratio ≈ current ratio for DAM. The high quick ratio reflects: (1) ₹99 Cr cash, (2) ₹92 Cr short-term investments, and (3) very low current liabilities of ₹40 Cr. DAM can survive for years without any new deal revenue — financial fortress balance sheet.
B7: Quick Ratio | C7: (CA − Curr Investments) / Current Liabilities | D7: =IF(' DAM Capital Financial Data'!C39=0,0,(' DAM Capital Financial Data'!C57-' DAM Capital Financial Data'!C52)/' DAM Capital Financial Data'!C39) -> 0.84444444 | E7: =IF(' DAM Capital Financial Data'!D39=0,0,(' DAM Capital Financial Data'!D57-' DAM Capital Financial Data'!D52)/' DAM Capital Financial Data'!D39) -> 1.3474265 | F7: =IF(' DAM Capital Financial Data'!E39=0,0,(' DAM Capital Financial Data'!E57-' DAM Capital Financial Data'!E52)/' DAM Capital Financial Data'!E39) -> 1.2263001 | G7: =IF(' DAM Capital Financial Data'!F39=0,0,(' DAM Capital Financial Data'!F57-' DAM Capital Financial Data'!F52)/' DAM Capital Financial Data'!F39) -> 0.085638438 | H7: =IF(' DAM Capital Financial Data'!G39=0,0,(' DAM Capital Financial Data'!G57-' DAM Capital Financial Data'!G52)/' DAM Capital Financial Data'!G39) -> 5.2250812 | I7: 0.3x – 1.0x (Pure cash) | J7: Cash ratio of 2.47x in FY24 means DAM holds ₹2.47 in cash/near-cash for every ₹1 of current liabilities. This is the hallmark of a company with zero capital requirements and high free cash flow generation. Excess cash creates pressure to deploy via dividends or buybacks — DAM has been paying regular dividends. The 'problem' of excess cash is a good problem to have.
B8: Cash Ratio | C8: Cash & Equivalents / Current Liabilities | D8: =IF(' DAM Capital Financial Data'!C39=0,0,' DAM Capital Financial Data'!C54/' DAM Capital Financial Data'!C39) -> 0.17777778 | E8: =IF(' DAM Capital Financial Data'!D39=0,0,' DAM Capital Financial Data'!D54/' DAM Capital Financial Data'!D39) -> 0.65651261 | F8: =IF(' DAM Capital Financial Data'!E39=0,0,' DAM Capital Financial Data'!E54/' DAM Capital Financial Data'!E39) -> 0.40628386 | G8: =IF(' DAM Capital Financial Data'!F39=0,0,' DAM Capital Financial Data'!F54/' DAM Capital Financial Data'!F39) -> 0.035335369 | H8: =IF(' DAM Capital Financial Data'!G39=0,0,' DAM Capital Financial Data'!G54/' DAM Capital Financial Data'!G39) -> 2.4731451
B10: PROFITABILITY RATIOS
B11: Ratio | C11: Formula / Meaning | D11: FY2020 | E11: FY2021 | F11: FY2022 | G11: FY2023 | H11: FY2024 | I11: Ideal Range | J11: 📖 What It Means & Inference for DAM Capital
B12: EBITDA Margin | C12: EBITDA / Revenue | D12: =IF(' DAM Capital Financial Data'!C5=0,0,' DAM Capital Financial Data'!C13/' DAM Capital Financial Data'!C5) -> 0.89361702 | E12: =IF(' DAM Capital Financial Data'!D5=0,0,' DAM Capital Financial Data'!D13/' DAM Capital Financial Data'!D5) -> 0.81494483 | F12: =IF(' DAM Capital Financial Data'!E5=0,0,' DAM Capital Financial Data'!E13/' DAM Capital Financial Data'!E5) -> 0.93267652 | G12: =IF(' DAM Capital Financial Data'!F5=0,0,' DAM Capital Financial Data'!F13/' DAM Capital Financial Data'!F5) -> 0.92509823 | H12: =IF(' DAM Capital Financial Data'!G5=0,0,' DAM Capital Financial Data'!G13/' DAM Capital Financial Data'!G5) -> 0.95989989 | I12: 25% – 50% (Investment banking) | J12: EBITDA margin of 95.99% in FY24 is world-class — comparable to top global investment banks. This reflects the fee-based, capital-light model: no cost of goods sold, no inventory, no heavy fixed assets. Every incremental deal is almost pure margin. The margin expansion from 89.4% (FY20) to 96% (FY24) confirms operating leverage as revenue scaled. Sustaining this requires protecting fee rates and controlling variable compensation.
B13: Operating Margin | C13: EBIT / Revenue | D13: =IF(' DAM Capital Financial Data'!C5=0,0,' DAM Capital Financial Data'!C15/' DAM Capital Financial Data'!C5) -> 0.80851064 | E13: =IF(' DAM Capital Financial Data'!D5=0,0,' DAM Capital Financial Data'!D15/' DAM Capital Financial Data'!D5) -> 0.66449348 | F13: =IF(' DAM Capital Financial Data'!E5=0,0,' DAM Capital Financial Data'!E15/' DAM Capital Financial Data'!E5) -> 0.87794198 | G13: =IF(' DAM Capital Financial Data'!F5=0,0,' DAM Capital Financial Data'!F15/' DAM Capital Financial Data'!F5) -> 0.86370334 | H13: =IF(' DAM Capital Financial Data'!G5=0,0,' DAM Capital Financial Data'!G15/' DAM Capital Financial Data'!G5) -> 0.92652948 | I13: 20% – 45% (IBD operating margin) | J13: Operating margin of 92.7% in FY24 (FY20: 80.9%) demonstrates exceptional scalability. As deal volume grows, most new revenue drops directly to EBIT since incremental costs are minimal. This is the 'royalty model' of finance — once relationships and reputation are established, each new mandate costs very little to execute. The 12pp margin expansion over 5 years is impressive and structurally defensible.
B14: Net Profit Margin | C14: Net Profit / Revenue | D14: =IF(' DAM Capital Financial Data'!C5=0,0,' DAM Capital Financial Data'!C18/' DAM Capital Financial Data'!C5) -> 0.0085106383 | E14: =IF(' DAM Capital Financial Data'!D5=0,0,' DAM Capital Financial Data'!D18/' DAM Capital Financial Data'!D5) -> 0.0072718154 | F14: =IF(' DAM Capital Financial Data'!E5=0,0,' DAM Capital Financial Data'!E18/' DAM Capital Financial Data'!E5) -> -0.067214012 | G14: =IF(' DAM Capital Financial Data'!F5=0,0,' DAM Capital Financial Data'!F18/' DAM Capital Financial Data'!F5) -> -0.038801572 | H14: =IF(' DAM Capital Financial Data'!G5=0,0,' DAM Capital Financial Data'!G18/' DAM Capital Financial Data'!G5) -> -0.13843159 | I14: 15% – 35% (Net after tax) | J14: Net margin of 35.75% in FY24 (up from -16.2% in FY20 when the company was loss-making pre-scale) confirms the turnaround story is complete. DAM crossed the profitability inflection point around FY22. The trajectory — negative → 18.4% → 4.3% → 35.8% — reflects India's IPO boom driving fee income. Risk: this margin will compress in a market downturn when deal volume dries up (demonstrated in FY20-FY21).
B15: Return on Assets (ROA) | C15: Net Profit / Total Assets | D15: =IF(' DAM Capital Financial Data'!C58=0,0,' DAM Capital Financial Data'!C18/' DAM Capital Financial Data'!C58) -> 0.0033613445 | E15: =IF(' DAM Capital Financial Data'!D58=0,0,' DAM Capital Financial Data'!D18/' DAM Capital Financial Data'!D58) -> 0.0023573403 | F15: =IF(' DAM Capital Financial Data'!E58=0,0,' DAM Capital Financial Data'!E18/' DAM Capital Financial Data'!E58) -> -0.030309014 | G15: =IF(' DAM Capital Financial Data'!F58=0,0,' DAM Capital Financial Data'!F18/' DAM Capital Financial Data'!F58) -> -0.0025070809 | H15: =IF(' DAM Capital Financial Data'!G58=0,0,' DAM Capital Financial Data'!G18/' DAM Capital Financial Data'!G58) -> -0.06893782 | I15: 12% – 25% (Capital efficiency) | J15: ROA of 17.8% in FY24 means for every ₹100 of total assets, DAM generates ₹17.8 of profit. This is outstanding — 2-3x better than most financial companies. The key is minimal asset base (₹361 Cr total assets) against growing profits (₹64 Cr PAT). Compare with HDFC Bank's ROA of ~1.8% — investment banking is inherently higher ROA than balance sheet businesses.
B16: Return on Equity (ROE) | C16: Net Profit / Total Shareholders Funds | D16: =IF(' DAM Capital Financial Data'!C27=0,0,' DAM Capital Financial Data'!C18/' DAM Capital Financial Data'!C27) -> 0.0054054054 | E16: =IF(' DAM Capital Financial Data'!D27=0,0,' DAM Capital Financial Data'!D18/' DAM Capital Financial Data'!D27) -> 0.0046126929 | F16: =IF(' DAM Capital Financial Data'!E27=0,0,' DAM Capital Financial Data'!E18/' DAM Capital Financial Data'!E27) -> -0.072243793 | G16: =IF(' DAM Capital Financial Data'!F27=0,0,' DAM Capital Financial Data'!F18/' DAM Capital Financial Data'!F27) -> -0.034573304 | H16: =IF(' DAM Capital Financial Data'!G27=0,0,' DAM Capital Financial Data'!G18/' DAM Capital Financial Data'!G27) -> -0.15554306 | I16: 20% – 40% (Boutique IB target) | J16: ROE of 40.2% in FY24 is exceptional, driven by fat margins and minimal equity base. This is not leverage-driven (D/E is nearly zero) — it is genuine earnings power. Sustainable ROE of 35-45% for a pure-play investment banking advisory firm in India's growing ECM market is achievable. Risk: if profits collapse in a market downturn and equity base stays large (post-IPO proceeds), ROE normalises down toward 15-20%.
B17: ROCE | C17: EBIT / (Total Assets − Current Liabilities) | D17: =IF((' DAM Capital Financial Data'!C58-' DAM Capital Financial Data'!C39)=0,0,' DAM Capital Financial Data'!C15/(' DAM Capital Financial Data'!C58-' DAM Capital Financial Data'!C39)) -> 0.51351351 | E17: =IF((' DAM Capital Financial Data'!D58-' DAM Capital Financial Data'!D39)=0,0,' DAM Capital Financial Data'!D15/(' DAM Capital Financial Data'!D58-' DAM Capital Financial Data'!D39)) -> 0.31198493 | F17: =IF((' DAM Capital Financial Data'!E58-' DAM Capital Financial Data'!E39)=0,0,' DAM Capital Financial Data'!E15/(' DAM Capital Financial Data'!E58-' DAM Capital Financial Data'!E39)) -> 0.62296101 | G17: =IF((' DAM Capital Financial Data'!F58-' DAM Capital Financial Data'!F39)=0,0,' DAM Capital Financial Data'!F15/(' DAM Capital Financial Data'!F58-' DAM Capital Financial Data'!F39)) -> 0.44882593 | H17: =IF((' DAM Capital Financial Data'!G58-' DAM Capital Financial Data'!G39)=0,0,' DAM Capital Financial Data'!G15/(' DAM Capital Financial Data'!G58-' DAM Capital Financial Data'!G39)) -> 0.51893963 | I17: N/A — Highly variable for IB | J17: ROCE of 51.9% (FY24) confirms exceptional capital efficiency. Investment banks with minimal capital deployment should always show high ROCE. The FY23 ROCE of 44.9% was suppressed by the artificially inflated balance sheet from client ECM flows. Structural ROCE of 40-55% reflects DAM's franchise value — one that is difficult for new entrants to replicate without years of relationship-building.
B18: FCF Margin | C18: Free Cash Flow / Revenue | D18: =IF(' DAM Capital Financial Data'!C5=0,0,' DAM Capital Financial Data'!C66/' DAM Capital Financial Data'!C5) -> 0.19148936 | E18: =IF(' DAM Capital Financial Data'!D5=0,0,' DAM Capital Financial Data'!D66/' DAM Capital Financial Data'!D5) -> 0.85255767 | F18: =IF(' DAM Capital Financial Data'!E5=0,0,' DAM Capital Financial Data'!E66/' DAM Capital Financial Data'!E5) -> 0.37766831 | G18: =IF(' DAM Capital Financial Data'!F5=0,0,' DAM Capital Financial Data'!F66/' DAM Capital Financial Data'!F5) -> 8.3128684 | H18: =IF(' DAM Capital Financial Data'!G5=0,0,' DAM Capital Financial Data'!G66/' DAM Capital Financial Data'!G5) -> -3.320356 | I18: 20% – 50% (Cash-converting) | J18: FCF margin is highly volatile for DAM due to lumpy ECM deal flows. The FY23 FCF margin of 831% (!) reflects ₹677 Cr of operating cash flow from massive client security deposits (current liabilities spike). Strip out these one-time flows and normalised FCF margin is 40-60%. DAM's business generates cash efficiently — CapEx is <₹3 Cr annually. The structural FCF story is very strong.
B20: EFFICIENCY / ACTIVITY RATIOS
B21: Ratio | C21: Formula / Meaning | D21: FY2020 | E21: FY2021 | F21: FY2022 | G21: FY2023 | H21: FY2024 | I21: Ideal Range | J21: 📖 What It Means & Inference for DAM Capital
